Workbook

Sheet Instructions
A2: How to use this template builder | G2: Instructions (clickon each step to find the tab to fill in)
B3: Tab group | C3: Included tabs to be filled out | G3: 1. Identify the location you are targeting for the templates and enter details in the Country_description tab
A4: Tabs groups to fill out | B4: Building_loads | C4: Building features, Schedules, Building loads, etc. | G4: 2. Identify different internal gains packages and create regonizable names.
B5: HVAC | C5: Heating, Cooling, Ventilation, DHW | G5: 3. Identify types of HVAC systems you want in the templates and fill out corresponding values.
B6: Construction | C6: Roof, Walls, Windows, etc. | G6: 4. Identify types of ventilation systems you want in the templates
B7: Building retrofits | C7: Retrofit package design | G7: 5. Identify types of DHW systems you want in the templates and fill out corresponding values.
G8: 6. Create HVAC and DHW packages from your constructions
G9: 7. Generate constructions based on the provided material lists for different building components
G10: 8. Add together constructions to create a full envelope assembly, and assign a name to each assembly
A11: Guidance/Calculation tabs (no action needed) | B11: Materials_choices | G11: 9. (OPTIONAL) Assign retrofit packages to each "template" for different internal components
B12: Drop_downs
B13: Units
B14: Material_assembly_generator
B15: Schedule_choices | G15: General guidance
B16: Constructions_assmebly | G16: Follow the instructions in the green highlighted text in each tab
B17: HVAC_options | G17: Legend
H18: Fill out this tab
H19: Support tab
A20: Ready to upload to website? | B20: Save this excel and send to MIT team for next steps | H20: Fill in
H21: Drop down options

Sheet Country_description
A1: Fill out here general information about the building stock for the location you are working on
A2: Parameter | B2: Value | C2: Guidance
A3: Location_type | B3: City | C3: Enter the type of location you are considering for this template assignment | O3: description for Seoul, Korea
A4: Location_name | B4: Seoul | C4: Share the name of the region in English | O4: Overview Seoul, the capital of the Republic of Korea, is one of the most densely developed cities in the country and contains a large and highly heterogeneous building stock composed of both residential and non-residential buildings. The current building stock has been shaped by rapid urbanization, large-scale housing supply programs, and repeated cycles of redevelopment and reconstruction. Pronounced differences exist between central and peripheral districts, as well as between low-rise residential neighborhoods and large apartment complexes, resulting in substantial variation in building age, construction type, and energy use characteristics. Average Costs Building asset values in Seoul are among the highest in South Korea and vary significantly by location and building use. Residential buildings—particularly apartment complexes—exhibit high unit prices, while non-residential buildings such as office, commercial, and hospitality facilities show wide variation in construction costs and asset values depending on size, function, and location. Overall, Seoul’s building stock is characterized by high development density and relatively high operating cost burdens due to land scarcity and intensive urban use. Construction Types (in order of commonality) Residential Buildings • Multi-family Housing (Apartments) Apartments are the dominant residential building type in Seoul. These buildings are typically mid- to high-rise reinforced concrete structures, often exceeding five stories, and were largely constructed during major housing supply waves beginning in the 1990s. • Single-Family Homes Despite the prominence of apartment living, single-family homes account for a very large share of the total building count in Seoul. These buildings are typically low-rise and consist of a mix of masonry and reinforced concrete structures. Many are relatively old and exhibit low energy performance. • Low-rise Multi-family Housing (Row houses and small apartment buildings) These buildings are generally two to five stories tall and are widely distributed throughout residential districts. While individually small, they constitute a significant portion of Seoul’s residential building stock. Non-residential Buildings (Based on the 19-category building classification framework provided in the project dataset) • Neighborhood Living Facilities (Type 1 and 2) These are the most widely distributed non-residential buildings in Seoul by count. Typically low- to mid-rise reinforced concrete structures, they are commonly mixed with residential uses and form the backbone of everyday urban activity. • Office Buildings Office buildings are concentrated in central business districts and sub-centers and are generally mid- to high-rise reinforced concrete or composite structures. Cooling and ventilation loads dominate their energy use. • Educational Facilities Schools and research buildings are typically large-scale, long-life structures with relatively stable occupancy patterns. • Medical Facilities Hospitals and related facilities are characterized by continuous operation and high dependence on mechanical systems. • Retail, Accommodation, and Cultural/Assembly Facilities These buildings support commercial, tourism, and cultural activities and tend to exhibit high energy use intensities and strong temporal variability in occupancy and loads. Construction History Across both residential and non-residential sectors, reinforced concrete construction overwhelmingly dominates Seoul’s building stock. This reflects historical priorities related to fire safety, durability, and the need for high-density development. Buildings constructed prior to the 1980s generally lack meaningful thermal insulation, and many single-family homes and low-rise neighborhood facilities from this period exhibit particularly poor envelope performance. Beginning in the early 2000s, the introduction and subsequent strengthening of the Building Energy Conservation Design Standards led to the systematic application of minimum thermal and system efficiency requirements across residential, office, educational, retail, and other non-residential buildings. As a result, year of construction has become a key proxy for energy performance within Seoul’s building stock. Average Age and Renovation Cycles The average age of buildings in Seoul is approximately 30 years, with a high proportion of aging structures in both residential and non-residential categories. Residential buildings typically undergo interior renovations and system upgrades every 15–30 years, while non-residential buildings experience more frequent partial renovations driven by tenant turnover, functional changes, and regulatory requirements. Major structural changes are often implemented through redevelopment or reconstruction rather than incremental retrofits. Heating and HVAC Equipment Residential • Natural Gas Boilers: The most common heating system • District Heating: Predominantly used in large apartment complexes • Electric or Oil-based Systems: Limited to specific cases, often in older single-family homes Non-residential • Central boilers and chillers: Common in office, medical, and educational buildings • Packaged and split HVAC systems: Widely used in neighborhood living facilities and small commercial buildings • VAV / CAV systems: Typical in large office and public buildings Compared to residential buildings, non-residential buildings in Seoul exhibit significantly higher cooling, ventilation, and electricity-driven loads. Energy Cost Environment Seoul operates under the national electricity and gas pricing structure of South Korea. Historically, natural gas prices have remained relatively low and stable, making gas-based heating systems economically attractive across both residential and non-residential buildings. This has led to a strong lock-in of gas and district heating systems within the existing building stock. More recently, rising electricity prices and energy transition policies have increased interest in electrified systems such as heat pumps. However, widespread adoption in existing buildings remains constrained by economic, technical, and structural barriers.
A5: Location_primary_language | B5: Korean | C5: Share the primary language spoken in this location in English
A6: Location_description | B6: Overview 서울특별시는 대한민국에서 가장 고밀도로 개발된 도시로, 주거·비주거 건물이 혼재된 대규모 건물 스톡을 보유하고 있다. 건물들은 급격한 도시 확장과 재개발·재건축 과정을 거치며 형성되었고, 건설 시기와 용도에 따른 이질성이 매우 큰 것이 특징이다. 도심부와 외곽 지역, 그리고 저층 주거 밀집지와 대규모 아파트 단지 간에는 건축 연식, 구조 형식, 에너지 사용 특성에서 뚜렷한 차이가 존재한다. Average Costs 서울의 건물 자산 가치는 대한민국 내에서 가장 높은 수준을 보이며, 입지와 용도에 따라 큰 편차를 가진다. 주거용 건물은 특히 아파트 단지를 중심으로 높은 단가가 형성되어 있으며, 비주거 건물 또한 업무시설, 판매시설, 숙박시설 등 용도에 따라 연면적당 건설비와 자산 가치가 크게 달라진다. 고밀 개발과 토지 희소성으로 인해, 서울의 건물 스톡은 전반적으로 높은 집약도와 높은 운영비 부담 구조를 가진다. Construction Types (in order of commonality) Residential Buildings • 공동주택 (아파트) 서울에서 가장 대표적인 주거 유형으로, 주로 5층 이상 중·고층 철근콘크리트 구조이다. 대규모 단지 형태로 조성되었으며, 1990년대 이후 집중적으로 공급되었다. • 단독주택 서울 주거 건물 중 절대적인 동(棟) 수 비중이 매우 높은 유형으로, 주로 저층이며 조적조 또는 철근콘크리트 구조가 혼재한다. 연식이 길고 에너지 성능이 낮은 건물이 다수를 차지한다. • 다가구·다세대주택 2 ~ 5층 규모의 저층 공동주택으로, 주거지역 전반에 널리 분포한다. 아파트에 비해 개별 건물 규모는 작으나, 도시 주거 스톡에서 중요한 비중을 차지한다. Non-residential Buildings (빌딩분류타입 엑셀의 19개 비주거 유형 체계를 전제로 함) • 근린생활시설 (제1·2종) 서울 전역에 가장 광범위하게 분포한 비주거 유형으로, 저층 또는 중층 철근콘크리트 구조가 일반적이다. 주거와 혼합된 형태로 존재하며 건물 수 기준 비중이 매우 높다. • 업무시설 도심 및 부도심을 중심으로 분포하며, 중·고층 철근콘크리트 또는 철골 구조가 일반적이다. 냉방 및 환기 부하가 지배적인 건물군이다. • 교육시설 학교 및 연구시설로 구성되며, 비교적 대규모 부지와 장수명 구조를 가진다. • 의료시설 병원 및 관련 시설로 구성되며, 연중 상시 운영과 높은 설비 의존도를 특징으로 한다. • 판매시설·숙박시설·문화·집회시설 상업 및 관광 기능을 담당하며, 이용 패턴의 변동성이 크고 에너지 사용 밀도가 높은 경향을 보인다. Construction History 서울의 건물은 주거·비주거를 막론하고 철근콘크리트 구조가 지배적이다. 이는 화재 안전, 내구성, 고밀 개발 요구에 따른 결과이다. 1980년대 이전에 건설된 건물은 단열 기준이 거의 적용되지 않았으며, 단독주택과 저층 근린생활시설을 중심으로 외피 성능이 매우 취약하다. 2000년대 이후 「건축물의 에너지절약설계기준」의 도입과 개정을 통해, 주거뿐 아니라 업무시설, 교육시설, 판매시설 등 비주거 건물에도 외피 및 설비 성능 기준이 단계적으로 적용되었다. 이로 인해 건축 연식은 서울 건물 스톡에서 에너지 성능을 설명하는 핵심 변수로 작용한다. Average Age and Renovation Cycles 서울의 건물 평균 연식은 약 30년 내외로, 주거용과 비주거용 모두 노후 건물 비율이 높다. 주거 건물은 15 ~ 30년 주기로 내부 리모델링 및 설비 교체가 이루어지며, 비주거 건물은 임차인 교체 및 용도 변경에 따라 부분적인 개보수가 반복적으로 수행된다. 대규모 구조 변경은 재건축·재개발 사업을 통해 이루어지는 경우가 많다. Heating and HVAC Equipment Residential • 도시가스 보일러: 가장 보편적인 난방 방식 • 지역난방: 대규모 아파트 단지 중심 • 전기·기름 보일러: 일부 노후 단독주택 및 특수 사례 Non-residential • 중앙식 보일러 및 냉동기 시스템: 업무·의료·교육시설 • 개별 냉난방 및 패키지 공조기: 근린생활시설, 소규모 업무시설 • VAV / CAV 시스템: 대형 업무 및 공공건물 비주거 건물은 주거 건물에 비해 냉방, 환기, 전력 부하의 비중이 높다. Energy Cost Environment 서울은 대한민국의 전력·가스 요금 체계를 그대로 적용받으며, 장기간 도시가스 기반 난방이 경제적으로 유리한 환경을 유지해 왔다. 이로 인해 주거·비주거 모두에서 가스 기반 난방 시스템이 널리 보급되었다. 최근에는 전기요금 변동성과 에너지 전환 정책의 영향으로 전기 기반 설비의 도입 가능성이 확대되고 있으나, 기존 건물 스톡에서는 여전히 가스 및 지역난방 의존도가 높다. | C6: Share a detailed description of the historical context of the building stock. This should include details around construction history, energy price environments, policies, etc. An Example is shared here for Massachusetts
A7: Location_description_translated | B7: As noted next to it | C7: Translated version of the description into primary language
A8: Existing_GIS_data_link | C8: OPTIONAL: Location of GIS data for 3d building footprints
A9: Bibliography | C9: OPTIONAL: List of sources used as reference for all the information in this excel

Sheet Mapping>>

Sheet component_options
A1: Region | B1: Typology | C1: Age_bracket | D1: AtticVentilation | F1: RoofInsulation | G1: AtticFloorInsulation | H1: BasementCeilingInsulation | I1: BasementWallsInsulation | J1: BasementFloorInsulation | K1: Weatherization | L1: Wall | M1: Windows | N1: Heating | O1: Cooling | P1: Distribution | Q1: DHW | R1: Equipment | S1: Lighting | T1: Thermostat
A2: MA | B2: SFH | C2: pre_1975 | D2: UnventilatedAttic | F2: UninsulatedRoof | G2: UninsulatedFloor | H2: UninsulatedCeiling | I2: UninsulatedWalls | J2: UninsulatedGroundSlab | K2: LeakyEnvelope | L2: UninsulatedWalls | M2: SinglePane | N2: ElectricResistance | O2: ACWindow | P2: Steam | Q2: ElectricResistanceDHW | R2: LowEfficiencyEquipment | S2: NoLED | T2: NoControls
B3: MFH | C3: btw_1975_2003 | D3: VentilatedAttic | F3: LimitedInsulationRoof | G3: LimitedInsulationFloor | H3: InsulatedCeiling | I3: InsulatedWalls | J3: InsulatedGroundSlab | K3: SomewhatLeakyEnvelope | L3: SomeInsulationWalls | M3: SinglePaneStormWindows | N3: OilHeating | O3: ACCentral | P3: HotWaterUninsulated | Q3: NaturalGasDHW | R3: HighEfficiencyEquipment | S3: LED | T3: Controls
C4: post_2003 | F4: HighlyInsulatedRoof | G4: HighlyInsulatedFloor | K4: TightEnvelope | L4: SIP | M4: DoublePaneLowE | N4: NaturalGasHeating | O4: WindowASHP | P4: AirDuctsUninsulated | Q4: NaturalGasHeatingDHWCombo
L5: FullInsulationWallsCavity | M5: TriplePaneLowE | N5: NaturalGasCondensingHeating | O5: ASHPCooling | P5: AirDuctsConditionedUninsulated | Q5: HPWH
L6: FullInsulationWallsCavityExterior | N6: ASHPHeating | O6: GSHPCooling | P6: HotWaterInsulated
N7: GSHPHeating | P7: AirDuctsInsulated

Sheet mapping
A1: Components | B1: Region | C1: Typology | D1: Age_bracket | E1: AtticVentilation | F1: RoofInsulation | G1: AtticFloorInsulation | H1: BasementCeilingInsulation | I1: BasementWallsInsulation | J1: BasementFloorInsulation | K1: Weatherization | L1: Wall | M1: Windows | N1: Heating | O1: Cooling | P1: Distribution | Q1: DHW | R1: Equipment | S1: Thermostat | T1: Lighting
A2: Space_use_assembly
A3: Occupancy | B3: Y | C3: Y
A4: Lighting | B4: Y | C4: Y | T4: Y
A5: Power | B5: Y | C5: Y | R5: Y
A6: Thermostat | B6: Y | S6: Y
A7: Water_flow | B7: Y | C7: Y
A8: Systems_assembly | B8: Y | C8: Y | N8: Y | O8: Y | P8: Y | Q8: Y
A9: Conditioning_constructor | B9: Y | N9: Y | O9: Y | P9: Y
A10: Heating | B10: Y | N10: Y | P10: Y
A11: Cooling | B11: Y | O11: Y | P11: Y
A12: Ventilation_constructor | B12: Y | C12: Y | K12: Y
A13: DHW_constructor | B13: Y | C13: Y | Q13: Y
A14: Envelope_assembly
A15: Construction_assembly
A16: FlatRoof | B16: Y | C16: Y | D16: Y | F16: Y
A17: AtticRoof | B17: Y | C17: Y | D17: Y | F17: Y
A18: AtticFloor | B18: Y | C18: Y | G18: Y
A19: Facade | B19: Y | C19: Y | D19: Y | L19: Y
A20: Partition | B20: Y | C20: Y
A21: GroundWall | B21: Y | C21: Y | I21: Y
A22: GroundSlab | B22: Y | C22: Y | J22: Y
A23: BasementCeiling | B23: Y | C23: Y | H23: Y
A24: FloorCeiling | B24: Y | C24: Y
A25: Window | B25: Y | C25: Y | M25: Y
A26: Infiltration | B26: Y | C26: Y | K26: Y
A27: AtticInfiltration | B27: Y | C27: Y | E27: Y | K27: Y
A28: ExternalFloor | B28: Y | C28: Y

Sheet generated_mapping
A1: This is the autogenerated set of labels for each of the tags. Please use these as your chosen labels when going through and assigning names and values
A2: Space_use_assembly | B2: Occupancy | C2: Lighting | D2: Power | E2: Setpoints | F2: Water_flow | G2: Systems_assembly | H2: Conditioning_constructor | I2: Heating | J2: Cooling | K2: Ventilation_constructor | L2: DHW_constructor | M2: Envelope_assembly | N2: Construction_components | O2: Roof | P2: Walls | Q2: Partition | R2: GroundWalls | S2: Slab | T2: Window | U2: Infiltration
A3: MA_SFH_Low_efficiency_equipment_NoControls_NoLED | B3: MA_SFH | C3: MA_SFH_NoLED | D3: MA_SFH_Low_efficiency_equipment | E3: MA_NoControls | F3: MA_SFH | G3: MA_SFH_Electric_resistance_AC_window_Steam_Electric_resistance_DHW | H3: MA_Electric_resistance_AC_window_Steam | I3: Electric_resistance_Steam | J3: AC_window_Steam | K3: MA_SFH | L3: MA_Electric_resistance_DHW | M3: MA_SFH_pre_1975_Occupied_uninsulated_Leaky_envelope_Uninsulated_walls_Single_pane | N3: MA_SFH_pre_1975_Occupied_uninsulated | O3: MA_SFH_Occupied_uninsulated | P3: MA_pre_1975_Uninsulated_walls | Q3: MA_pre_1975 | R3: MA_pre_1975 | S3: MA_pre_1975 | T3: MA_Single_pane | U3: MA_Leaky_envelope
A4: MA_SFH_Low_efficiency_equipment_NoControls_LED | B4: MA_MFH | C4: MA_SFH_LED | D4: MA_SFH_EnergyStar_equipment | E4: MA_Controls | F4: MA_MFH | G4: MA_SFH_Electric_resistance_AC_window_Steam_NG_DHW | H4: MA_Electric_resistance_AC_window_Hot_water_uninsulated | I4: Electric_resistance_Hot_water_uninsulated | J4: AC_window_Hot_water_uninsulated | K4: MA_MFH | L4: MA_NG_DHW | M4: MA_SFH_pre_1975_Occupied_uninsulated_Leaky_envelope_Uninsulated_walls_Single_pane_storm_windows | N4: MA_SFH_pre_1975_Unoccupied_uninsulated_floor | O4: MA_SFH_Unoccupied_uninsulated_floor | P4: MA_pre_1975_Some_wall_insulation | Q4: MA_btw_1975_2003 | R4: MA_btw_1975_2003 | S4: MA_btw_1975_2003 | T4: MA_Single_pane_storm_windows | U4: MA_Somewhat_leaky_envelope
A5: MA_SFH_Low_efficiency_equipment_Controls_NoLED | C5: MA_MFH_NoLED | D5: MA_MFH_Low_efficiency_equipment | G5: MA_SFH_Electric_resistance_AC_window_Steam_Heating_DHW_combo_NG | H5: MA_Electric_resistance_AC_window_Air_ducts_uninsulated | I5: Electric_resistance_Air_ducts_uninsulated | J5: AC_window_Air_ducts_uninsulated | L5: MA_Heating_DHW_combo_NG | M5: MA_SFH_pre_1975_Occupied_uninsulated_Leaky_envelope_Uninsulated_walls_Double_pane_lowE | N5: MA_SFH_pre_1975_Unoccupied_insulated_floor | O5: MA_SFH_Unoccupied_insulated_floor | P5: MA_pre_1975_SIP | Q5: MA_post_2003 | R5: MA_post_2003 | S5: MA_post_2003 | T5: MA_Double_pane_lowE | U5: MA_Tight_envelope_HRV
A6: MA_SFH_Low_efficiency_equipment_Controls_LED | C6: MA_MFH_LED | D6: MA_MFH_EnergyStar_equipment | G6: MA_SFH_Electric_resistance_AC_window_Steam_HPWH | H6: MA_Electric_resistance_AC_window_Air_ducts_conditioned_uninsulated | I6: Electric_resistance_Air_ducts_conditioned_uninsulated | J6: AC_window_Air_ducts_conditioned_uninsulated | L6: MA_HPWH | M6: MA_SFH_pre_1975_Occupied_uninsulated_Leaky_envelope_Uninsulated_walls_Triple_pane_lowE | N6: MA_SFH_pre_1975_Limited_insulation_roof | O6: MA_SFH_Limited_insulation_roof | P6: MA_pre_1975_Full_insulated_wall_cavity | T6: MA_Triple_pane_lowE
A7: MA_SFH_EnergyStar_equipment_NoControls_NoLED | G7: MA_SFH_Electric_resistance_AC_window_Hot_water_uninsulated_Electric_resistance_DHW | H7: MA_Electric_resistance_AC_window_Hot_water_insulated | I7: Electric_resistance_Hot_water_insulated | J7: AC_window_Hot_water_insulated | M7: MA_SFH_pre_1975_Occupied_uninsulated_Leaky_envelope_Some_wall_insulation_Single_pane | N7: MA_SFH_pre_1975_Insulation_roof | O7: MA_SFH_Insulation_roof | P7: MA_pre_1975_Full_insulated_wall_cavity_exterior
A8: MA_SFH_EnergyStar_equipment_NoControls_LED | G8: MA_SFH_Electric_resistance_AC_window_Hot_water_uninsulated_NG_DHW | H8: MA_Electric_resistance_AC_window_Air_ducts_insulated | I8: Electric_resistance_Air_ducts_insulated | J8: AC_window_Air_ducts_insulated | M8: MA_SFH_pre_1975_Occupied_uninsulated_Leaky_envelope_Some_wall_insulation_Single_pane_storm_windows | N8: MA_SFH_pre_1975_Occupied_insulated | O8: MA_SFH_Occupied_insulated | P8: MA_btw_1975_2003_Uninsulated_walls
A9: MA_SFH_EnergyStar_equipment_Controls_NoLED | G9: MA_SFH_Electric_resistance_AC_window_Hot_water_uninsulated_Heating_DHW_combo_NG | H9: MA_Electric_resistance_Central_AC_Steam | I9: Oil_heating_Steam | J9: Central_AC_Steam | M9: MA_SFH_pre_1975_Occupied_uninsulated_Leaky_envelope_Some_wall_insulation_Double_pane_lowE | N9: MA_SFH_pre_1975_Unoccupied_high_insulated_floor | O9: MA_SFH_Unoccupied_high_insulated_floor | P9: MA_btw_1975_2003_Some_wall_insulation
A10: MA_SFH_EnergyStar_equipment_Controls_LED | G10: MA_SFH_Electric_resistance_AC_window_Hot_water_uninsulated_HPWH | H10: MA_Electric_resistance_Central_AC_Hot_water_uninsulated | I10: Oil_heating_Hot_water_uninsulated | J10: Central_AC_Hot_water_uninsulated | M10: MA_SFH_pre_1975_Occupied_uninsulated_Leaky_envelope_Some_wall_insulation_Triple_pane_lowE | N10: MA_SFH_btw_1975_2003_Occupied_uninsulated | O10: MA_MFH_Occupied_uninsulated | P10: MA_btw_1975_2003_SIP
A11: MA_MFH_Low_efficiency_equipment_NoControls_NoLED | G11: MA_SFH_Electric_resistance_AC_window_Air_ducts_uninsulated_Electric_resistance_DHW | H11: MA_Electric_resistance_Central_AC_Air_ducts_uninsulated | I11: Oil_heating_Air_ducts_uninsulated | J11: Central_AC_Air_ducts_uninsulated | M11: MA_SFH_pre_1975_Occupied_uninsulated_Leaky_envelope_SIP_Single_pane | N11: MA_SFH_btw_1975_2003_Unoccupied_uninsulated_floor | O11: MA_MFH_Unoccupied_uninsulated_floor | P11: MA_btw_1975_2003_Full_insulated_wall_cavity
A12: MA_MFH_Low_efficiency_equipment_NoControls_LED | G12: MA_SFH_Electric_resistance_AC_window_Air_ducts_uninsulated_NG_DHW | H12: MA_Electric_resistance_Central_AC_Air_ducts_conditioned_uninsulated | I12: Oil_heating_Air_ducts_conditioned_uninsulated | J12: Central_AC_Air_ducts_conditioned_uninsulated | M12: MA_SFH_pre_1975_Occupied_uninsulated_Leaky_envelope_SIP_Single_pane_storm_windows | N12: MA_SFH_btw_1975_2003_Unoccupied_insulated_floor | O12: MA_MFH_Unoccupied_insulated_floor | P12: MA_btw_1975_2003_Full_insulated_wall_cavity_exterior
A13: MA_MFH_Low_efficiency_equipment_Controls_NoLED | G13: MA_SFH_Electric_resistance_AC_window_Air_ducts_uninsulated_Heating_DHW_combo_NG | H13: MA_Electric_resistance_Central_AC_Hot_water_insulated | I13: Oil_heating_Hot_water_insulated | J13: Central_AC_Hot_water_insulated | M13: MA_SFH_pre_1975_Occupied_uninsulated_Leaky_envelope_SIP_Double_pane_lowE | N13: MA_SFH_btw_1975_2003_Limited_insulation_roof | O13: MA_MFH_Limited_insulation_roof | P13: MA_post_2003_Uninsulated_walls
A14: MA_MFH_Low_efficiency_equipment_Controls_LED | G14: MA_SFH_Electric_resistance_AC_window_Air_ducts_uninsulated_HPWH | H14: MA_Electric_resistance_Central_AC_Air_ducts_insulated | I14: Oil_heating_Air_ducts_insulated | J14: Central_AC_Air_ducts_insulated | M14: MA_SFH_pre_1975_Occupied_uninsulated_Leaky_envelope_SIP_Triple_pane_lowE | N14: MA_SFH_btw_1975_2003_Insulation_roof | O14: MA_MFH_Insulation_roof | P14: MA_post_2003_Some_wall_insulation
A15: MA_MFH_EnergyStar_equipment_NoControls_NoLED | G15: MA_SFH_Electric_resistance_AC_window_Air_ducts_conditioned_uninsulated_Electric_resistance_DHW | H15: MA_Electric_resistance_Natural_ventilation_Steam | I15: NG_heating_Steam | J15: Natural_ventilation_Steam | M15: MA_SFH_pre_1975_Occupied_uninsulated_Leaky_envelope_Full_insulated_wall_cavity_Single_pane | N15: MA_SFH_btw_1975_2003_Occupied_insulated | O15: MA_MFH_Occupied_insulated | P15: MA_post_2003_SIP
A16: MA_MFH_EnergyStar_equipment_NoControls_LED | G16: MA_SFH_Electric_resistance_AC_window_Air_ducts_conditioned_uninsulated_NG_DHW | H16: MA_Electric_resistance_Natural_ventilation_Hot_water_uninsulated | I16: NG_heating_Hot_water_uninsulated | J16: Natural_ventilation_Hot_water_uninsulated | M16: MA_SFH_pre_1975_Occupied_uninsulated_Leaky_envelope_Full_insulated_wall_cavity_Single_pane_storm_windows | N16: MA_SFH_btw_1975_2003_Unoccupied_high_insulated_floor | O16: MA_MFH_Unoccupied_high_insulated_floor | P16: MA_post_2003_Full_insulated_wall_cavity
A17: MA_MFH_EnergyStar_equipment_Controls_NoLED | G17: MA_SFH_Electric_resistance_AC_window_Air_ducts_conditioned_uninsulated_Heating_DHW_combo_NG | H17: MA_Electric_resistance_Natural_ventilation_Air_ducts_uninsulated | I17: NG_heating_Air_ducts_uninsulated | J17: Natural_ventilation_Air_ducts_uninsulated | M17: MA_SFH_pre_1975_Occupied_uninsulated_Leaky_envelope_Full_insulated_wall_cavity_Double_pane_lowE | N17: MA_SFH_post_2003_Occupied_uninsulated | P17: MA_post_2003_Full_insulated_wall_cavity_exterior
A18: MA_MFH_EnergyStar_equipment_Controls_LED | G18: MA_SFH_Electric_resistance_AC_window_Air_ducts_conditioned_uninsulated_HPWH | H18: MA_Electric_resistance_Natural_ventilation_Air_ducts_conditioned_uninsulated | I18: NG_heating_Air_ducts_conditioned_uninsulated | J18: Natural_ventilation_Air_ducts_conditioned_uninsulated | M18: MA_SFH_pre_1975_Occupied_uninsulated_Leaky_envelope_Full_insulated_wall_cavity_Triple_pane_lowE | N18: MA_SFH_post_2003_Unoccupied_uninsulated_floor
G19: MA_SFH_Electric_resistance_AC_window_Hot_water_insulated_Electric_resistance_DHW | H19: MA_Electric_resistance_Natural_ventilation_Hot_water_insulated | I19: NG_heating_Hot_water_insulated | J19: Natural_ventilation_Hot_water_insulated | M19: MA_SFH_pre_1975_Occupied_uninsulated_Leaky_envelope_Full_insulated_wall_cavity_exterior_Single_pane | N19: MA_SFH_post_2003_Unoccupied_insulated_floor
G20: MA_SFH_Electric_resistance_AC_window_Hot_water_insulated_NG_DHW | H20: MA_Electric_resistance_Natural_ventilation_Air_ducts_insulated | I20: NG_heating_Air_ducts_insulated | J20: Natural_ventilation_Air_ducts_insulated | M20: MA_SFH_pre_1975_Occupied_uninsulated_Leaky_envelope_Full_insulated_wall_cavity_exterior_Single_pane_storm_windows | N20: MA_SFH_post_2003_Limited_insulation_roof
G21: MA_SFH_Electric_resistance_AC_window_Hot_water_insulated_Heating_DHW_combo_NG | H21: MA_Electric_resistance_Window_ASHP_Steam | I21: NG_condensing_heating_Steam | J21: Window_ASHP_Steam | M21: MA_SFH_pre_1975_Occupied_uninsulated_Leaky_envelope_Full_insulated_wall_cavity_exterior_Double_pane_lowE | N21: MA_SFH_post_2003_Insulation_roof
G22: MA_SFH_Electric_resistance_AC_window_Hot_water_insulated_HPWH | H22: MA_Electric_resistance_Window_ASHP_Hot_water_uninsulated | I22: NG_condensing_heating_Hot_water_uninsulated | J22: Window_ASHP_Hot_water_uninsulated | M22: MA_SFH_pre_1975_Occupied_uninsulated_Leaky_envelope_Full_insulated_wall_cavity_exterior_Triple_pane_lowE | N22: MA_SFH_post_2003_Occupied_insulated
G23: MA_SFH_Electric_resistance_AC_window_Air_ducts_insulated_Electric_resistance_DHW | H23: MA_Electric_resistance_Window_ASHP_Air_ducts_uninsulated | I23: NG_condensing_heating_Air_ducts_uninsulated | J23: Window_ASHP_Air_ducts_uninsulated | M23: MA_SFH_pre_1975_Occupied_uninsulated_Somewhat_leaky_envelope_Uninsulated_walls_Single_pane | N23: MA_SFH_post_2003_Unoccupied_high_insulated_floor
G24: MA_SFH_Electric_resistance_AC_window_Air_ducts_insulated_NG_DHW | H24: MA_Electric_resistance_Window_ASHP_Air_ducts_conditioned_uninsulated | I24: NG_condensing_heating_Air_ducts_conditioned_uninsulated | J24: Window_ASHP_Air_ducts_conditioned_uninsulated | M24: MA_SFH_pre_1975_Occupied_uninsulated_Somewhat_leaky_envelope_Uninsulated_walls_Single_pane_storm_windows | N24: MA_MFH_pre_1975_Occupied_uninsulated
G25: MA_SFH_Electric_resistance_AC_window_Air_ducts_insulated_Heating_DHW_combo_NG | H25: MA_Electric_resistance_Window_ASHP_Hot_water_insulated | I25: NG_condensing_heating_Hot_water_insulated | J25: Window_ASHP_Hot_water_insulated | M25: MA_SFH_pre_1975_Occupied_uninsulated_Somewhat_leaky_envelope_Uninsulated_walls_Double_pane_lowE | N25: MA_MFH_pre_1975_Unoccupied_uninsulated_floor
G26: MA_SFH_Electric_resistance_AC_window_Air_ducts_insulated_HPWH | H26: MA_Electric_resistance_Window_ASHP_Air_ducts_insulated | I26: NG_condensing_heating_Air_ducts_insulated | J26: Window_ASHP_Air_ducts_insulated | M26: MA_SFH_pre_1975_Occupied_uninsulated_Somewhat_leaky_envelope_Uninsulated_walls_Triple_pane_lowE | N26: MA_MFH_pre_1975_Unoccupied_insulated_floor
G27: MA_SFH_Electric_resistance_Central_AC_Steam_Electric_resistance_DHW | H27: MA_Electric_resistance_ASHP_Steam | I27: ASHP_Steam | J27: ASHP_Steam | M27: MA_SFH_pre_1975_Occupied_uninsulated_Somewhat_leaky_envelope_Some_wall_insulation_Single_pane | N27: MA_MFH_pre_1975_Limited_insulation_roof
G28: MA_SFH_Electric_resistance_Central_AC_Steam_NG_DHW | H28: MA_Electric_resistance_ASHP_Hot_water_uninsulated | I28: ASHP_Hot_water_uninsulated | J28: ASHP_Hot_water_uninsulated | M28: MA_SFH_pre_1975_Occupied_uninsulated_Somewhat_leaky_envelope_Some_wall_insulation_Single_pane_storm_windows | N28: MA_MFH_pre_1975_Insulation_roof
G29: MA_SFH_Electric_resistance_Central_AC_Steam_Heating_DHW_combo_NG | H29: MA_Electric_resistance_ASHP_Air_ducts_uninsulated | I29: ASHP_Air_ducts_uninsulated | J29: ASHP_Air_ducts_uninsulated | M29: MA_SFH_pre_1975_Occupied_uninsulated_Somewhat_leaky_envelope_Some_wall_insulation_Double_pane_lowE | N29: MA_MFH_pre_1975_Occupied_insulated
G30: MA_SFH_Electric_resistance_Central_AC_Steam_HPWH | H30: MA_Electric_resistance_ASHP_Air_ducts_conditioned_uninsulated | I30: ASHP_Air_ducts_conditioned_uninsulated | J30: ASHP_Air_ducts_conditioned_uninsulated | M30: MA_SFH_pre_1975_Occupied_uninsulated_Somewhat_leaky_envelope_Some_wall_insulation_Triple_pane_lowE | N30: MA_MFH_pre_1975_Unoccupied_high_insulated_floor
... G38: MA_SFH_Electric_resistance_Central_AC_Air_ducts_uninsulated_HPWH | H38: MA_Electric_resistance_GSHP_Air_ducts_insulated | I38: GSHP_Air_ducts_insulated | J38: GSHP_Air_ducts_insulated | M38: MA_SFH_pre_1975_Occupied_uninsulated_Somewhat_leaky_envelope_Full_insulated_wall_cavity_Triple_pane_lowE | N38: MA_MFH_post_2003_Occupied_uninsulated
G39: MA_SFH_Electric_resistance_Central_AC_Air_ducts_conditioned_uninsulated_Electric_resistance_DHW | H39: MA_Oil_heating_AC_window_Steam | M39: MA_SFH_pre_1975_Occupied_uninsulated_Somewhat_leaky_envelope_Full_insulated_wall_cavity_exterior_Single_pane | N39: MA_MFH_post_2003_Unoccupied_uninsulated_floor
G40: MA_SFH_Electric_resistance_Central_AC_Air_ducts_conditioned_uninsulated_NG_DHW | H40: MA_Oil_heating_AC_window_Hot_water_uninsulated | M40: MA_SFH_pre_1975_Occupied_uninsulated_Somewhat_leaky_envelope_Full_insulated_wall_cavity_exterior_Single_pane_storm_windows | N40: MA_MFH_post_2003_Unoccupied_insulated_floor
G41: MA_SFH_Electric_resistance_Central_AC_Air_ducts_conditioned_uninsulated_Heating_DHW_combo_NG | H41: MA_Oil_heating_AC_window_Air_ducts_uninsulated | M41: MA_SFH_pre_1975_Occupied_uninsulated_Somewhat_leaky_envelope_Full_insulated_wall_cavity_exterior_Double_pane_lowE | N41: MA_MFH_post_2003_Limited_insulation_roof
G42: MA_SFH_Electric_resistance_Central_AC_Air_ducts_conditioned_uninsulated_HPWH | H42: MA_Oil_heating_AC_window_Air_ducts_conditioned_uninsulated | M42: MA_SFH_pre_1975_Occupied_uninsulated_Somewhat_leaky_envelope_Full_insulated_wall_cavity_exterior_Triple_pane_lowE | N42: MA_MFH_post_2003_Insulation_roof
G43: MA_SFH_Electric_resistance_Central_AC_Hot_water_insulated_Electric_resistance_DHW | H43: MA_Oil_heating_AC_window_Hot_water_insulated | M43: MA_SFH_pre_1975_Occupied_uninsulated_Tight_envelope_HRV_Uninsulated_walls_Single_pane | N43: MA_MFH_post_2003_Occupied_insulated
G44: MA_SFH_Electric_resistance_Central_AC_Hot_water_insulated_NG_DHW | H44: MA_Oil_heating_AC_window_Air_ducts_insulated | M44: MA_SFH_pre_1975_Occupied_uninsulated_Tight_envelope_HRV_Uninsulated_walls_Single_pane_storm_windows | N44: MA_MFH_post_2003_Unoccupied_high_insulated_floor
G45: MA_SFH_Electric_resistance_Central_AC_Hot_water_insulated_Heating_DHW_combo_NG | H45: MA_Oil_heating_Central_AC_Steam | M45: MA_SFH_pre_1975_Occupied_uninsulated_Tight_envelope_HRV_Uninsulated_walls_Double_pane_lowE
G46: MA_SFH_Electric_resistance_Central_AC_Hot_water_insulated_HPWH | H46: MA_Oil_heating_Central_AC_Hot_water_uninsulated | M46: MA_SFH_pre_1975_Occupied_uninsulated_Tight_envelope_HRV_Uninsulated_walls_Triple_pane_lowE
G47: MA_SFH_Electric_resistance_Central_AC_Air_ducts_insulated_Electric_resistance_DHW | H47: MA_Oil_heating_Central_AC_Air_ducts_uninsulated | M47: MA_SFH_pre_1975_Occupied_uninsulated_Tight_envelope_HRV_Some_wall_insulation_Single_pane
...

Sheet Internal_gains
A1: Choose the metric you want to define from the dropdown | B1: Does not need to be filled in, will automatically populate | C1: Fill in the value for the chosen metric | D1: Does not need to be filled in, will automatically populate | E1: Name your variable. This should be something to recognize for the template assignment
A2: Variable | B2: Description | C2: Value | D2: Unit | E2: Variable_naming
A3: Occupant_density | B3: {=_xludf.XLOOKUP(A3,Units!$A$2:$A$100,Units!$C$2:$C$100,"")} -> #NAME? | D3: {=_xludf.XLOOKUP(A3,Units!$A$2:$A$100,Units!$B$2:$B$100,"")} -> #NAME? | E3: Occupancy_1
A4: Occupant_density | B4: {=_xludf.XLOOKUP(A4,Units!$A$2:$A$100,Units!$C$2:$C$100,"")} -> #NAME? | D4: {=_xludf.XLOOKUP(A4,Units!$A$2:$A$100,Units!$B$2:$B$100,"")} -> #NAME? | E4: Occupancy_2
A5: Power_density | B5: {=_xludf.XLOOKUP(A5,Units!$A$2:$A$100,Units!$C$2:$C$100,"")} -> #NAME? | D5: {=_xludf.XLOOKUP(A5,Units!$A$2:$A$100,Units!$B$2:$B$100,"")} -> #NAME? | E5: Power_1 | F5: Add another unit kWh per year/m2
A6: Power_density | B6: {=_xludf.XLOOKUP(A6,Units!$A$2:$A$100,Units!$C$2:$C$100,"")} -> #NAME? | D6: {=_xludf.XLOOKUP(A6,Units!$A$2:$A$100,Units!$B$2:$B$100,"")} -> #NAME? | E6: Power_2
A7: Lighting_density | B7: {=_xludf.XLOOKUP(A7,Units!$A$2:$A$100,Units!$C$2:$C$100,"")} -> #NAME? | D7: {=_xludf.XLOOKUP(A7,Units!$A$2:$A$100,Units!$B$2:$B$100,"")} -> #NAME? | E7: Lighting_1
A8: Lighting_density | B8: {=_xludf.XLOOKUP(A8,Units!$A$2:$A$100,Units!$C$2:$C$100,"")} -> #NAME? | D8: {=_xludf.XLOOKUP(A8,Units!$A$2:$A$100,Units!$B$2:$B$100,"")} -> #NAME? | E8: Lighting_2
A9: Occupant_density | B9: {=_xludf.XLOOKUP(A9,Units!$A$2:$A$100,Units!$C$2:$C$100,"")} -> #NAME? | D9: {=_xludf.XLOOKUP(A9,Units!$A$2:$A$100,Units!$B$2:$B$100,"")} -> #NAME?
A10: Schedules | B10: {=_xludf.XLOOKUP(A10,Units!$A$2:$A$100,Units!$C$2:$C$100,"")} -> #NAME? | D10: {=_xludf.XLOOKUP(A10,Units!$A$2:$A$100,Units!$B$2:$B$100,"")} -> #NAME?
A11: Schedules | B11: {=IF(_xludf.XLOOKUP(A11,Units!$A$2:$A$100,Units!$C$2:$C$100,"")=0,"",_xludf.XLOOKUP(A11,Units!$A$2:$A$100,Units!$C$2:$C$100,""))} -> #NAME? | D11: {=IF(_xludf.XLOOKUP(A11,Units!$A$2:$A$100,Units!$B$2:$B$100,"")=0,"",_xludf.XLOOKUP(A11,Units!$A$2:$A$100,Units!$B$2:$B$100,""))} -> #NAME?
A12: Lighting_density | B12: {=IF(_xludf.XLOOKUP(A12,Units!$A$2:$A$100,Units!$C$2:$C$100,"")=0,"",_xludf.XLOOKUP(A12,Units!$A$2:$A$100,Units!$C$2:$C$100,""))} -> #NAME? | C12: 5.6 | D12: {=IF(_xludf.XLOOKUP(A12,Units!$A$2:$A$100,Units!$B$2:$B$100,"")=0,"",_xludf.XLOOKUP(A12,Units!$A$2:$A$100,Units!$B$2:$B$100,""))} -> #NAME?
B13: {=IF(_xludf.XLOOKUP(A13,Units!$A$2:$A$100,Units!$C$2:$C$100,"")=0,"",_xludf.XLOOKUP(A13,Units!$A$2:$A$100,Units!$C$2:$C$100,""))} -> #NAME? | D13: {=IF(_xludf.XLOOKUP(A13,Units!$A$2:$A$100,Units!$B$2:$B$100,"")=0,"",_xludf.XLOOKUP(A13,Units!$A$2:$A$100,Units!$B$2:$B$100,""))} -> #NAME?
B14: {=IF(_xludf.XLOOKUP(A14,Units!$A$2:$A$100,Units!$C$2:$C$100,"")=0,"",_xludf.XLOOKUP(A14,Units!$A$2:$A$100,Units!$C$2:$C$100,""))} -> #NAME? | D14: {=IF(_xludf.XLOOKUP(A14,Units!$A$2:$A$100,Units!$B$2:$B$100,"")=0,"",_xludf.XLOOKUP(A14,Units!$A$2:$A$100,Units!$B$2:$B$100,""))} -> #NAME?
B15: {=IF(_xludf.XLOOKUP(A15,Units!$A$2:$A$100,Units!$C$2:$C$100,"")=0,"",_xludf.XLOOKUP(A15,Units!$A$2:$A$100,Units!$C$2:$C$100,""))} -> #NAME? | D15: {=IF(_xludf.XLOOKUP(A15,Units!$A$2:$A$100,Units!$B$2:$B$100,"")=0,"",_xludf.XLOOKUP(A15,Units!$A$2:$A$100,Units!$B$2:$B$100,""))} -> #NAME?
B16: {=IF(_xludf.XLOOKUP(A16,Units!$A$2:$A$100,Units!$C$2:$C$100,"")=0,"",_xludf.XLOOKUP(A16,Units!$A$2:$A$100,Units!$C$2:$C$100,""))} -> #NAME? | D16: {=IF(_xludf.XLOOKUP(A16,Units!$A$2:$A$100,Units!$B$2:$B$100,"")=0,"",_xludf.XLOOKUP(A16,Units!$A$2:$A$100,Units!$B$2:$B$100,""))} -> #NAME?
B17: {=IF(_xludf.XLOOKUP(A17,Units!$A$2:$A$100,Units!$C$2:$C$100,"")=0,"",_xludf.XLOOKUP(A17,Units!$A$2:$A$100,Units!$C$2:$C$100,""))} -> #NAME? | D17: {=IF(_xludf.XLOOKUP(A17,Units!$A$2:$A$100,Units!$B$2:$B$100,"")=0,"",_xludf.XLOOKUP(A17,Units!$A$2:$A$100,Units!$B$2:$B$100,""))} -> #NAME?
B18: {=IF(_xludf.XLOOKUP(A18,Units!$A$2:$A$100,Units!$C$2:$C$100,"")=0,"",_xludf.XLOOKUP(A18,Units!$A$2:$A$100,Units!$C$2:$C$100,""))} -> #NAME? | D18: {=IF(_xludf.XLOOKUP(A18,Units!$A$2:$A$100,Units!$B$2:$B$100,"")=0,"",_xludf.XLOOKUP(A18,Units!$A$2:$A$100,Units!$B$2:$B$100,""))} -> #NAME?
B19: {=IF(_xludf.XLOOKUP(A19,Units!$A$2:$A$100,Units!$C$2:$C$100,"")=0,"",_xludf.XLOOKUP(A19,Units!$A$2:$A$100,Units!$C$2:$C$100,""))} -> #NAME? | D19: {=IF(_xludf.XLOOKUP(A19,Units!$A$2:$A$100,Units!$B$2:$B$100,"")=0,"",_xludf.XLOOKUP(A19,Units!$A$2:$A$100,Units!$B$2:$B$100,""))} -> #NAME?
B20: {=IF(_xludf.XLOOKUP(A20,Units!$A$2:$A$100,Units!$C$2:$C$100,"")=0,"",_xludf.XLOOKUP(A20,Units!$A$2:$A$100,Units!$C$2:$C$100,""))} -> #NAME? | D20: {=IF(_xludf.XLOOKUP(A20,Units!$A$2:$A$100,Units!$B$2:$B$100,"")=0,"",_xludf.XLOOKUP(A20,Units!$A$2:$A$100,Units!$B$2:$B$100,""))} -> #NAME?
B21: {=IF(_xludf.XLOOKUP(A21,Units!$A$2:$A$100,Units!$C$2:$C$100,"")=0,"",_xludf.XLOOKUP(A21,Units!$A$2:$A$100,Units!$C$2:$C$100,""))} -> #NAME? | D21: {=IF(_xludf.XLOOKUP(A21,Units!$A$2:$A$100,Units!$B$2:$B$100,"")=0,"",_xludf.XLOOKUP(A21,Units!$A$2:$A$100,Units!$B$2:$B$100,""))} -> #NAME?
B22: {=IF(_xludf.XLOOKUP(A22,Units!$A$2:$A$100,Units!$C$2:$C$100,"")=0,"",_xludf.XLOOKUP(A22,Units!$A$2:$A$100,Units!$C$2:$C$100,""))} -> #NAME? | D22: {=IF(_xludf.XLOOKUP(A22,Units!$A$2:$A$100,Units!$B$2:$B$100,"")=0,"",_xludf.XLOOKUP(A22,Units!$A$2:$A$100,Units!$B$2:$B$100,""))} -> #NAME?
B23: {=IF(_xludf.XLOOKUP(A23,Units!$A$2:$A$100,Units!$C$2:$C$100,"")=0,"",_xludf.XLOOKUP(A23,Units!$A$2:$A$100,Units!$C$2:$C$100,""))} -> #NAME? | D23: {=IF(_xludf.XLOOKUP(A23,Units!$A$2:$A$100,Units!$B$2:$B$100,"")=0,"",_xludf.XLOOKUP(A23,Units!$A$2:$A$100,Units!$B$2:$B$100,""))} -> #NAME?
B24: {=IF(_xludf.XLOOKUP(A24,Units!$A$2:$A$100,Units!$C$2:$C$100,"")=0,"",_xludf.XLOOKUP(A24,Units!$A$2:$A$100,Units!$C$2:$C$100,""))} -> #NAME? | D24: {=IF(_xludf.XLOOKUP(A24,Units!$A$2:$A$100,Units!$B$2:$B$100,"")=0,"",_xludf.XLOOKUP(A24,Units!$A$2:$A$100,Units!$B$2:$B$100,""))} -> #NAME?
... B139: {=IF(_xludf.XLOOKUP(A139,Units!$A$2:$A$100,Units!$C$2:$C$100,"")=0,"",_xludf.XLOOKUP(A139,Units!$A$2:$A$100,Units!$C$2:$C$100,""))} -> #NAME? | D139: {=IF(_xludf.XLOOKUP(A139,Units!$A$2:$A$100,Units!$B$2:$B$100,"")=0,"",_xludf.XLOOKUP(A139,Units!$A$2:$A$100,Units!$B$2:$B$100,""))} -> #NAME?

Sheet Building_loads>>>>

Sheet Occupancy
A1: Name your variable. This should be something to recognize for the template assignment | B1: Fill in this column with the occupant density per variable/type of building you choose. | E1: The occupancy schedule can be either self-designed in the three schedule tabs, or you can pick from the set of provided options
A2: Name | B2: Occupant_density | C2: MetabolicRate | D2: Occupant_units | E2: Occupant_schedule | F2: Source
A3: KR_res_sf | B3: 0.03 | C3: 1.2 | D3: person/m2 | E3: Residential_Occupancy_Year | F3: 건축물 에너지효율등급 인증제도 운영규정 [별표2] 주거 및 주거용 이외 건축물 용도프로필 / Operating Regulations for the Building Energy Rating System [Appendix 2]: Use Profiles for Residential and Non-Residential Buildings
A4: KR_res_mf_low | B4: 0.03 | C4: 1.2 | D4: person/m2 | E4: Residential_Occupancy_Year | F4: 건축물 에너지효율등급 인증제도 운영규정 [별표2] 주거 및 주거용 이외 건축물 용도프로필 / Operating Regulations for the Building Energy Rating System [Appendix 2]: Use Profiles for Residential and Non-Residential Buildings
A5: KR_res_mf_high | B5: 0.03 | C5: 1.2 | D5: person/m2 | E5: Residential_Occupancy_Year | F5: 건축물 에너지효율등급 인증제도 운영규정 [별표2] 주거 및 주거용 이외 건축물 용도프로필 / Operating Regulations for the Building Energy Rating System [Appendix 2]: Use Profiles for Residential and Non-Residential Buildings
A6: KR_office_small | B6: 0.039 | C6: 1.2 | D6: person/m2 | E6: Office_Occupancy_Year | F6: 건축물 에너지효율등급 인증제도 운영규정 [별표2] 주거 및 주거용 이외 건축물 용도프로필 / Operating Regulations for the Building Energy Rating System [Appendix 2]: Use Profiles for Residential and Non-Residential Buildings
A7: KR_office_medium | B7: 0.039 | C7: 1.2 | D7: person/m2 | E7: Office_Occupancy_Year | F7: 건축물 에너지효율등급 인증제도 운영규정 [별표2] 주거 및 주거용 이외 건축물 용도프로필 / Operating Regulations for the Building Energy Rating System [Appendix 2]: Use Profiles for Residential and Non-Residential Buildings
A8: KR_office_large | B8: 0.039 | C8: 1.2 | D8: person/m2 | E8: Office_Occupancy_Year | F8: 건축물 에너지효율등급 인증제도 운영규정 [별표2] 주거 및 주거용 이외 건축물 용도프로필 / Operating Regulations for the Building Energy Rating System [Appendix 2]: Use Profiles for Residential and Non-Residential Buildings
A9: KR_retail_small | B9: 0.07 | C9: 1.2 | D9: person/m2 | E9: Retail_Occupancy_Year | F9: 건축물 에너지효율등급 인증제도 운영규정 [별표2] 주거 및 주거용 이외 건축물 용도프로필 / Operating Regulations for the Building Energy Rating System [Appendix 2]: Use Profiles for Residential and Non-Residential Buildings
A10: KR_retail_medium | B10: 0.07 | C10: 1.2 | D10: person/m2 | E10: Retail_Occupancy_Year | F10: 건축물 에너지효율등급 인증제도 운영규정 [별표2] 주거 및 주거용 이외 건축물 용도프로필 / Operating Regulations for the Building Energy Rating System [Appendix 2]: Use Profiles for Residential and Non-Residential Buildings
A11: KR_retail_large | B11: 0.07 | C11: 1.2 | D11: person/m2 | E11: Retail_Occupancy_Year | F11: 건축물 에너지효율등급 인증제도 운영규정 [별표2] 주거 및 주거용 이외 건축물 용도프로필 / Operating Regulations for the Building Energy Rating System [Appendix 2]: Use Profiles for Residential and Non-Residential Buildings
A12: KR_school | B12: 0.305 | C12: 1.2 | D12: person/m2 | E12: School_Occupancy_Year | F12: 건축물 에너지효율등급 인증제도 운영규정 [별표2] 주거 및 주거용 이외 건축물 용도프로필 / Operating Regulations for the Building Energy Rating System [Appendix 2]: Use Profiles for Residential and Non-Residential Buildings
A13: KR_hospital | B13: 0.045 | C13: 1.2 | D13: person/m2 | E13: Hospital_Occupancy_Year | F13: 건축물 에너지효율등급 인증제도 운영규정 [별표2] 주거 및 주거용 이외 건축물 용도프로필 / Operating Regulations for the Building Energy Rating System [Appendix 2]: Use Profiles for Residential and Non-Residential Buildings
A14: KR_welfare | B14: 0.045 | C14: 1.2 | D14: person/m2 | E14: Hospital_Occupancy_Year | F14: 건축물 에너지효율등급 인증제도 운영규정 [별표2] 주거 및 주거용 이외 건축물 용도프로필 / Operating Regulations for the Building Energy Rating System [Appendix 2]: Use Profiles for Residential and Non-Residential Buildings
... A21: KR_etc | B21: 0 | C21: 1.2 | D21: person/m2 | E21: Industrial_Occupancy_Year | F21: 건축물 에너지효율등급 인증제도 운영규정 [별표2] 주거 및 주거용 이외 건축물 용도프로필 / Operating Regulations for the Building Energy Rating System [Appendix 2]: Use Profiles for Residential and Non-Residential Buildings

Sheet Lighting
A1: Name your variable. This should be something to recognize for the template assignment | B1: Fill in this column with the lighting density per variable/type of building you choose. | E1: The lighting schedule can be either self-designed in the three schedule tabs, or you can pick from the set of provided options
A2: Name | B2: Lighting_power_density | C2: DimmingType | D2: Lighting_schedule | E2: Lighting_power_density_unit | F2: Source
A3: KR_res_sf_LowEff | B3: 4.57 | C3: Off | D3: Residential_Lighting_Year | E3: W/m2 | F3: 2020년 에너지총조사_공개용 마이크로데이터/ 2020 Energy Consumption Survey: Public-Use Microdata
A4: KR_res_sf_Standard | B4: 3.39 | C4: Off | D4: Residential_Lighting_Year | E4: W/m2 | F4: 2020년 에너지총조사_공개용 마이크로데이터/ 2020 Energy Consumption Survey: Public-Use Microdata
A5: KR_res_sf_HighEff | B5: 1.52 | C5: Off | D5: Residential_Lighting_Year | E5: W/m2 | F5: 2020년 에너지총조사_공개용 마이크로데이터/ 2020 Energy Consumption Survey: Public-Use Microdata
A6: KR_res_mf_Low_LowEff | B6: 4.38 | C6: Off | D6: Residential_Lighting_Year | E6: W/m2 | F6: 2020년 에너지총조사_공개용 마이크로데이터/ 2020 Energy Consumption Survey: Public-Use Microdata
A7: KR_res_mf_Low_Standard | B7: 3.31 | C7: Off | D7: Residential_Lighting_Year | E7: W/m2 | F7: 2020년 에너지총조사_공개용 마이크로데이터/ 2020 Energy Consumption Survey: Public-Use Microdata
A8: KR_res_mf_Low_HighEff | B8: 2 | C8: Off | D8: Residential_Lighting_Year | E8: W/m2 | F8: 2020년 에너지총조사_공개용 마이크로데이터/ 2020 Energy Consumption Survey: Public-Use Microdata
A9: KR_res_mf_High_LowEff | B9: 4.63 | C9: Off | D9: Residential_Lighting_Year | E9: W/m2 | F9: 2020년 에너지총조사_공개용 마이크로데이터/ 2020 Energy Consumption Survey: Public-Use Microdata
A10: KR_res_mf_High_Standard | B10: 3.34 | C10: Off | D10: Residential_Lighting_Year | E10: W/m2 | F10: 2020년 에너지총조사_공개용 마이크로데이터/ 2020 Energy Consumption Survey: Public-Use Microdata
A11: KR_res_mf_High_HighEff | B11: 1.97 | C11: Off | D11: Residential_Lighting_Year | E11: W/m2 | F11: 2020년 에너지총조사_공개용 마이크로데이터/ 2020 Energy Consumption Survey: Public-Use Microdata
A12: KR_office_small_LowEff | B12: 6.69 | C12: Off | D12: Office_Lighting_Year | E12: W/m2 | F12: 2020년 에너지총조사_공개용 마이크로데이터/ 2020 Energy Consumption Survey: Public-Use Microdata
A13: KR_office_small_Standard | B13: 4.75 | C13: Off | D13: Office_Lighting_Year | E13: W/m2 | F13: 2020년 에너지총조사_공개용 마이크로데이터/ 2020 Energy Consumption Survey: Public-Use Microdata
A14: KR_office_small_HighEff | B14: 3.23 | C14: Off | D14: Office_Lighting_Year | E14: W/m2 | F14: 2020년 에너지총조사_공개용 마이크로데이터/ 2020 Energy Consumption Survey: Public-Use Microdata
... A59: KR_etc_HighEff | B59: 3.23 | C59: Off | D59: Industrial_Lighting_Year | E59: W/m2 | F59: 2020년 에너지총조사_공개용 마이크로데이터/ 2020 Energy Consumption Survey: Public-Use Microdata

Sheet Power
A1: Name your variable. This should be something to recognize for the template assignment | B1: Fill in this column with the equipment power density per variable/type of building you choose. | D1: The equipment schedule can be either self-designed in the three schedule tabs, or you can pick from the set of provided options
A2: Name | B2: Equipment_power_density | C2: Equipment_power_density_unit | D2: Equipment_schedule | E2: Sources
A3: KR_res_sf | B3: 2.17 | C3: W/m2 | D3: Residential_Equipment_Year | E3: 건축물 에너지효율등급 인증제도 운영규정 [별표2] 주거 및 주거용 이외 건축물 용도프로필 / Operating Regulations for the Building Energy Rating System [Appendix 2]: Use Profiles for Residential and Non-Residential Buildings
A4: KR_res_mf_low | B4: 2.17 | C4: W/m2 | D4: Residential_Equipment_Year | E4: 건축물 에너지효율등급 인증제도 운영규정 [별표2] 주거 및 주거용 이외 건축물 용도프로필 / Operating Regulations for the Building Energy Rating System [Appendix 2]: Use Profiles for Residential and Non-Residential Buildings
A5: KR_res_mf_high | B5: 2.17 | C5: W/m2 | D5: Residential_Equipment_Year | E5: 건축물 에너지효율등급 인증제도 운영규정 [별표2] 주거 및 주거용 이외 건축물 용도프로필 / Operating Regulations for the Building Energy Rating System [Appendix 2]: Use Profiles for Residential and Non-Residential Buildings
A6: KR_office_small | B6: 7.64 | C6: W/m2 | D6: Office_Equipment_Year | E6: 건축물 에너지효율등급 인증제도 운영규정 [별표2] 주거 및 주거용 이외 건축물 용도프로필 / Operating Regulations for the Building Energy Rating System [Appendix 2]: Use Profiles for Residential and Non-Residential Buildings
A7: KR_office_medium | B7: 7.64 | C7: W/m2 | D7: Office_Equipment_Year | E7: 건축물 에너지효율등급 인증제도 운영규정 [별표2] 주거 및 주거용 이외 건축물 용도프로필 / Operating Regulations for the Building Energy Rating System [Appendix 2]: Use Profiles for Residential and Non-Residential Buildings
A8: KR_office_large | B8: 7.64 | C8: W/m2 | D8: Office_Equipment_Year | E8: 건축물 에너지효율등급 인증제도 운영규정 [별표2] 주거 및 주거용 이외 건축물 용도프로필 / Operating Regulations for the Building Energy Rating System [Appendix 2]: Use Profiles for Residential and Non-Residential Buildings
A9: KR_retail_small | B9: 2.7 | C9: W/m2 | D9: Retail_Equipment_Year | E9: Ashrae Standard 90.1
A10: KR_retail_medium | B10: 2.7 | C10: W/m2 | D10: Retail_Equipment_Year | E10: Ashrae Standard 90.1
A11: KR_retail_large | B11: 2.7 | C11: W/m2 | D11: Retail_Equipment_Year | E11: Ashrae Standard 90.1
A12: KR_school | B12: 2.77 | C12: W/m2 | D12: School_Equipment_Year | E12: 건축물 에너지효율등급 인증제도 운영규정 [별표2] 주거 및 주거용 이외 건축물 용도프로필 / Operating Regulations for the Building Energy Rating System [Appendix 2]: Use Profiles for Residential and Non-Residential Buildings
A13: KR_hospital | B13: 10.8 | C13: W/m2 | D13: Hospital_Equipment_Year | E13: Ashrae Standard 90.1
A14: KR_welfare | B14: 10.8 | C14: W/m2 | D14: Hospital_Equipment_Year | E14: Ashrae Standard 90.1
... A21: KR_etc | B21: 0 | C21: W/m2 | D21: Industrial_Equipment_Year | E21: 건축물 에너지효율등급 인증제도 운영규정 [별표2] 주거 및 주거용 이외 건축물 용도프로필 / Operating Regulations for the Building Energy Rating System [Appendix 2]: Use Profiles for Residential and Non-Residential Buildings

Sheet Generated_schedule
A1: Schedule+type

Sheet Schedule_viewer
A1: View sample schedules here and alter them | B1: Schedule

Sheet HVAC
A1: Choose the metric you want to define from the dropdown | B1: Does not need to be filled in, will automatically populate | C1: Fill in the value for the chosen metric | D1: Does not need to be filled in, will automatically populate | E1: Name your variable. This should be something to recognize for the template assignment
A2: Variable | B2: Description | C2: Value | D2: Unit | E2: Variable_naming
A3: Heating_distribution_fluid | B3: {=_xludf.XLOOKUP(A3,Units!$A$2:$A$100,Units!$C$2:$C$100,"")} -> #NAME? | D3: {=_xludf.XLOOKUP(A3,Units!$A$2:$A$100,Units!$B$2:$B$100,"")} -> #NAME?
A4: Heating_setpoints | B4: {=_xludf.XLOOKUP(A4,Units!$A$2:$A$100,Units!$C$2:$C$100,"")} -> #NAME? | D4: {=_xludf.XLOOKUP(A4,Units!$A$2:$A$100,Units!$B$2:$B$100,"")} -> #NAME?
A5: Heating_distribution_temperature | B5: {=_xludf.XLOOKUP(A5,Units!$A$2:$A$100,Units!$C$2:$C$100,"")} -> #NAME? | D5: {=_xludf.XLOOKUP(A5,Units!$A$2:$A$100,Units!$B$2:$B$100,"")} -> #NAME?
A6: Heating_setpoint_schedule | B6: {=_xludf.XLOOKUP(A6,Units!$A$2:$A$100,Units!$C$2:$C$100,"")} -> #NAME? | D6: {=_xludf.XLOOKUP(A6,Units!$A$2:$A$100,Units!$B$2:$B$100,"")} -> #NAME?
A7: Cooling_setpoints | B7: {=_xludf.XLOOKUP(A7,Units!$A$2:$A$100,Units!$C$2:$C$100,"")} -> #NAME? | D7: {=_xludf.XLOOKUP(A7,Units!$A$2:$A$100,Units!$B$2:$B$100,"")} -> #NAME?
A8: Cooling_setpoint_schedule | B8: {=_xludf.XLOOKUP(A8,Units!$A$2:$A$100,Units!$C$2:$C$100,"")} -> #NAME? | D8: {=_xludf.XLOOKUP(A8,Units!$A$2:$A$100,Units!$B$2:$B$100,"")} -> #NAME?
A9: Cooling_distribution_temperature | B9: {=_xludf.XLOOKUP(A9,Units!$A$2:$A$100,Units!$C$2:$C$100,"")} -> #NAME? | D9: {=_xludf.XLOOKUP(A9,Units!$A$2:$A$100,Units!$B$2:$B$100,"")} -> #NAME?
A10: Cooling_setpoint_schedule | B10: {=_xludf.XLOOKUP(A10,Units!$A$2:$A$100,Units!$C$2:$C$100,"")} -> #NAME? | D10: {=_xludf.XLOOKUP(A10,Units!$A$2:$A$100,Units!$B$2:$B$100,"")} -> #NAME?
A11: Minimum_fresh_air | B11: {=_xludf.XLOOKUP(A11,Units!$A$2:$A$100,Units!$C$2:$C$100,"")} -> #NAME? | D11: {=_xludf.XLOOKUP(A11,Units!$A$2:$A$100,Units!$B$2:$B$100,"")} -> #NAME?
A12: Heating_COP_penalty | B12: {=_xludf.XLOOKUP(A12,Units!$A$2:$A$100,Units!$C$2:$C$100,"")} -> #NAME? | D12: {=_xludf.XLOOKUP(A12,Units!$A$2:$A$100,Units!$B$2:$B$100,"")} -> #NAME?
A13: Cooling_COP_penalty | B13: {=_xludf.XLOOKUP(A13,Units!$A$2:$A$100,Units!$C$2:$C$100,"")} -> #NAME? | D13: {=_xludf.XLOOKUP(A13,Units!$A$2:$A$100,Units!$B$2:$B$100,"")} -> #NAME?
A14: Heating_setpoints | B14: {=IF(_xludf.XLOOKUP(A14,Units!$A$2:$A$100,Units!$C$2:$C$100,"")=0,"",_xludf.XLOOKUP(A14,Units!$A$2:$A$100,Units!$C$2:$C$100,""))} -> #NAME? | D14: {=IF(_xludf.XLOOKUP(A14,Units!$A$2:$A$100,Units!$B$2:$B$100,"")=0,"",_xludf.XLOOKUP(A14,Units!$A$2:$A$100,Units!$B$2:$B$100,""))} -> #NAME?
B15: {=IF(_xludf.XLOOKUP(A15,Units!$A$2:$A$100,Units!$C$2:$C$100,"")=0,"",_xludf.XLOOKUP(A15,Units!$A$2:$A$100,Units!$C$2:$C$100,""))} -> #NAME? | D15: {=IF(_xludf.XLOOKUP(A15,Units!$A$2:$A$100,Units!$B$2:$B$100,"")=0,"",_xludf.XLOOKUP(A15,Units!$A$2:$A$100,Units!$B$2:$B$100,""))} -> #NAME?
A16: Heating_setpoints | B16: {=IF(_xludf.XLOOKUP(A16,Units!$A$2:$A$100,Units!$C$2:$C$100,"")=0,"",_xludf.XLOOKUP(A16,Units!$A$2:$A$100,Units!$C$2:$C$100,""))} -> #NAME? | C16: 15 | D16: {=IF(_xludf.XLOOKUP(A16,Units!$A$2:$A$100,Units!$B$2:$B$100,"")=0,"",_xludf.XLOOKUP(A16,Units!$A$2:$A$100,Units!$B$2:$B$100,""))} -> #NAME?
A17: Heating_COP_penalty | B17: {=IF(_xludf.XLOOKUP(A17,Units!$A$2:$A$100,Units!$C$2:$C$100,"")=0,"",_xludf.XLOOKUP(A17,Units!$A$2:$A$100,Units!$C$2:$C$100,""))} -> #NAME? | C17: 5 | D17: {=IF(_xludf.XLOOKUP(A17,Units!$A$2:$A$100,Units!$B$2:$B$100,"")=0,"",_xludf.XLOOKUP(A17,Units!$A$2:$A$100,Units!$B$2:$B$100,""))} -> #NAME?
B18: {=IF(_xludf.XLOOKUP(A18,Units!$A$2:$A$100,Units!$C$2:$C$100,"")=0,"",_xludf.XLOOKUP(A18,Units!$A$2:$A$100,Units!$C$2:$C$100,""))} -> #NAME? | D18: {=IF(_xludf.XLOOKUP(A18,Units!$A$2:$A$100,Units!$B$2:$B$100,"")=0,"",_xludf.XLOOKUP(A18,Units!$A$2:$A$100,Units!$B$2:$B$100,""))} -> #NAME?
B19: {=IF(_xludf.XLOOKUP(A19,Units!$A$2:$A$100,Units!$C$2:$C$100,"")=0,"",_xludf.XLOOKUP(A19,Units!$A$2:$A$100,Units!$C$2:$C$100,""))} -> #NAME? | D19: {=IF(_xludf.XLOOKUP(A19,Units!$A$2:$A$100,Units!$B$2:$B$100,"")=0,"",_xludf.XLOOKUP(A19,Units!$A$2:$A$100,Units!$B$2:$B$100,""))} -> #NAME?
B20: {=IF(_xludf.XLOOKUP(A20,Units!$A$2:$A$100,Units!$C$2:$C$100,"")=0,"",_xludf.XLOOKUP(A20,Units!$A$2:$A$100,Units!$C$2:$C$100,""))} -> #NAME? | D20: {=IF(_xludf.XLOOKUP(A20,Units!$A$2:$A$100,Units!$B$2:$B$100,"")=0,"",_xludf.XLOOKUP(A20,Units!$A$2:$A$100,Units!$B$2:$B$100,""))} -> #NAME?
B21: {=IF(_xludf.XLOOKUP(A21,Units!$A$2:$A$100,Units!$C$2:$C$100,"")=0,"",_xludf.XLOOKUP(A21,Units!$A$2:$A$100,Units!$C$2:$C$100,""))} -> #NAME? | D21: {=IF(_xludf.XLOOKUP(A21,Units!$A$2:$A$100,Units!$B$2:$B$100,"")=0,"",_xludf.XLOOKUP(A21,Units!$A$2:$A$100,Units!$B$2:$B$100,""))} -> #NAME?
B22: {=IF(_xludf.XLOOKUP(A22,Units!$A$2:$A$100,Units!$C$2:$C$100,"")=0,"",_xludf.XLOOKUP(A22,Units!$A$2:$A$100,Units!$C$2:$C$100,""))} -> #NAME? | D22: {=IF(_xludf.XLOOKUP(A22,Units!$A$2:$A$100,Units!$B$2:$B$100,"")=0,"",_xludf.XLOOKUP(A22,Units!$A$2:$A$100,Units!$B$2:$B$100,""))} -> #NAME?
B23: {=IF(_xludf.XLOOKUP(A23,Units!$A$2:$A$100,Units!$C$2:$C$100,"")=0,"",_xludf.XLOOKUP(A23,Units!$A$2:$A$100,Units!$C$2:$C$100,""))} -> #NAME? | D23: {=IF(_xludf.XLOOKUP(A23,Units!$A$2:$A$100,Units!$B$2:$B$100,"")=0,"",_xludf.XLOOKUP(A23,Units!$A$2:$A$100,Units!$B$2:$B$100,""))} -> #NAME?
B24: {=IF(_xludf.XLOOKUP(A24,Units!$A$2:$A$100,Units!$C$2:$C$100,"")=0,"",_xludf.XLOOKUP(A24,Units!$A$2:$A$100,Units!$C$2:$C$100,""))} -> #NAME? | D24: {=IF(_xludf.XLOOKUP(A24,Units!$A$2:$A$100,Units!$B$2:$B$100,"")=0,"",_xludf.XLOOKUP(A24,Units!$A$2:$A$100,Units!$B$2:$B$100,""))} -> #NAME?
B25: {=IF(_xludf.XLOOKUP(A25,Units!$A$2:$A$100,Units!$C$2:$C$100,"")=0,"",_xludf.XLOOKUP(A25,Units!$A$2:$A$100,Units!$C$2:$C$100,""))} -> #NAME? | D25: {=IF(_xludf.XLOOKUP(A25,Units!$A$2:$A$100,Units!$B$2:$B$100,"")=0,"",_xludf.XLOOKUP(A25,Units!$A$2:$A$100,Units!$B$2:$B$100,""))} -> #NAME?
B26: {=IF(_xludf.XLOOKUP(A26,Units!$A$2:$A$100,Units!$C$2:$C$100,"")=0,"",_xludf.XLOOKUP(A26,Units!$A$2:$A$100,Units!$C$2:$C$100,""))} -> #NAME? | D26: {=IF(_xludf.XLOOKUP(A26,Units!$A$2:$A$100,Units!$B$2:$B$100,"")=0,"",_xludf.XLOOKUP(A26,Units!$A$2:$A$100,Units!$B$2:$B$100,""))} -> #NAME?
B27: {=IF(_xludf.XLOOKUP(A27,Units!$A$2:$A$100,Units!$C$2:$C$100,"")=0,"",_xludf.XLOOKUP(A27,Units!$A$2:$A$100,Units!$C$2:$C$100,""))} -> #NAME? | D27: {=IF(_xludf.XLOOKUP(A27,Units!$A$2:$A$100,Units!$B$2:$B$100,"")=0,"",_xludf.XLOOKUP(A27,Units!$A$2:$A$100,Units!$B$2:$B$100,""))} -> #NAME?
B28: {=IF(_xludf.XLOOKUP(A28,Units!$A$2:$A$100,Units!$C$2:$C$100,"")=0,"",_xludf.XLOOKUP(A28,Units!$A$2:$A$100,Units!$C$2:$C$100,""))} -> #NAME? | D28: {=IF(_xludf.XLOOKUP(A28,Units!$A$2:$A$100,Units!$B$2:$B$100,"")=0,"",_xludf.XLOOKUP(A28,Units!$A$2:$A$100,Units!$B$2:$B$100,""))} -> #NAME?
B29: {=IF(_xludf.XLOOKUP(A29,Units!$A$2:$A$100,Units!$C$2:$C$100,"")=0,"",_xludf.XLOOKUP(A29,Units!$A$2:$A$100,Units!$C$2:$C$100,""))} -> #NAME? | D29: {=IF(_xludf.XLOOKUP(A29,Units!$A$2:$A$100,Units!$B$2:$B$100,"")=0,"",_xludf.XLOOKUP(A29,Units!$A$2:$A$100,Units!$B$2:$B$100,""))} -> #NAME?
... B72: {=IF(_xludf.XLOOKUP(A72,Units!$A$2:$A$100,Units!$C$2:$C$100,"")=0,"",_xludf.XLOOKUP(A72,Units!$A$2:$A$100,Units!$C$2:$C$100,""))} -> #NAME? | D72: {=IF(_xludf.XLOOKUP(A72,Units!$A$2:$A$100,Units!$B$2:$B$100,"")=0,"",_xludf.XLOOKUP(A72,Units!$A$2:$A$100,Units!$B$2:$B$100,""))} -> #NAME?

Sheet Setpoints
A1: Name your variable. This should be something to recognize for the template assignment
A2: Name | B2: Setpoint_type | C2: Heating_setpoint | D2: Heating_schedule | E2: Cooling_setpoint | F2: Cooling_schedule | G2: Setpoint_units | H2: Sources
A3: KR_res_sf_NoControl | B3: Constant | C3: 20 | D3: Residential_Heating_Year | E3: 26 | F3: Residential_Cooling_Year | G3: Celsius | H3: 건축물 에너지효율등급 인증제도 운영규정 [별표2] 주거 및 주거용 이외 건축물 용도프로필 / Operating Regulations for the Building Energy Rating System [Appendix 2]: Use Profiles for Residential and Non-Residential Buildings
A4: KR_res_mf_low_NoControl | B4: Constant | C4: 20 | D4: Residential_Heating_Year | E4: 26 | F4: Residential_Cooling_Year | G4: Celsius | H4: 건축물 에너지효율등급 인증제도 운영규정 [별표2] 주거 및 주거용 이외 건축물 용도프로필 / Operating Regulations for the Building Energy Rating System [Appendix 2]: Use Profiles for Residential and Non-Residential Buildings
A5: KR_res_mf_high_NoControl | B5: Constant | C5: 20 | D5: Residential_Heating_Year | E5: 26 | F5: Residential_Cooling_Year | G5: Celsius | H5: 건축물 에너지효율등급 인증제도 운영규정 [별표2] 주거 및 주거용 이외 건축물 용도프로필 / Operating Regulations for the Building Energy Rating System [Appendix 2]: Use Profiles for Residential and Non-Residential Buildings
A6: KR_office_small_NoControl | B6: Constant | C6: 20 | D6: Office_Heating_Year | E6: 26 | F6: Office_Cooling_Year | G6: Celsius | H6: 건축물 에너지효율등급 인증제도 운영규정 [별표2] 주거 및 주거용 이외 건축물 용도프로필 / Operating Regulations for the Building Energy Rating System [Appendix 2]: Use Profiles for Residential and Non-Residential Buildings
A7: KR_office_medium_NoControl | B7: Constant | C7: 20 | D7: Office_Heating_Year | E7: 26 | F7: Office_Cooling_Year | G7: Celsius | H7: 건축물 에너지효율등급 인증제도 운영규정 [별표2] 주거 및 주거용 이외 건축물 용도프로필 / Operating Regulations for the Building Energy Rating System [Appendix 2]: Use Profiles for Residential and Non-Residential Buildings
A8: KR_office_large_NoControl | B8: Constant | C8: 20 | D8: Office_Heating_Year | E8: 26 | F8: Office_Cooling_Year | G8: Celsius | H8: 건축물 에너지효율등급 인증제도 운영규정 [별표2] 주거 및 주거용 이외 건축물 용도프로필 / Operating Regulations for the Building Energy Rating System [Appendix 2]: Use Profiles for Residential and Non-Residential Buildings
A9: KR_retail_small_NoControl | B9: Constant | C9: 20 | D9: Retail_Heating_Year | E9: 26 | F9: Retail_Cooling_Year | G9: Celsius | H9: 건축물 에너지효율등급 인증제도 운영규정 [별표2] 주거 및 주거용 이외 건축물 용도프로필 / Operating Regulations for the Building Energy Rating System [Appendix 2]: Use Profiles for Residential and Non-Residential Buildings
A10: KR_retail_medium_NoControl | B10: Constant | C10: 20 | D10: Retail_Heating_Year | E10: 26 | F10: Retail_Cooling_Year | G10: Celsius | H10: 건축물 에너지효율등급 인증제도 운영규정 [별표2] 주거 및 주거용 이외 건축물 용도프로필 / Operating Regulations for the Building Energy Rating System [Appendix 2]: Use Profiles for Residential and Non-Residential Buildings
A11: KR_retail_large_NoControl | B11: Constant | C11: 20 | D11: Retail_Heating_Year | E11: 26 | F11: Retail_Cooling_Year | G11: Celsius | H11: 건축물 에너지효율등급 인증제도 운영규정 [별표2] 주거 및 주거용 이외 건축물 용도프로필 / Operating Regulations for the Building Energy Rating System [Appendix 2]: Use Profiles for Residential and Non-Residential Buildings
A12: KR_school_NoControl | B12: Constant | C12: 20 | D12: School_Heating_Year | E12: 26 | F12: School_Cooling_Year | G12: Celsius | H12: 건축물 에너지효율등급 인증제도 운영규정 [별표2] 주거 및 주거용 이외 건축물 용도프로필 / Operating Regulations for the Building Energy Rating System [Appendix 2]: Use Profiles for Residential and Non-Residential Buildings
A13: KR_hospital_NoControl | B13: Constant | C13: 20 | D13: Hospital_Heating_Year | E13: 26 | F13: Hospital_Cooling_Year | G13: Celsius | H13: 건축물 에너지효율등급 인증제도 운영규정 [별표2] 주거 및 주거용 이외 건축물 용도프로필 / Operating Regulations for the Building Energy Rating System [Appendix 2]: Use Profiles for Residential and Non-Residential Buildings
A14: KR_welfare_NoControl | B14: Constant | C14: 20 | D14: Hospital_Heating_Year | E14: 26 | F14: Hospital_Cooling_Year | G14: Celsius | H14: 건축물 에너지효율등급 인증제도 운영규정 [별표2] 주거 및 주거용 이외 건축물 용도프로필 / Operating Regulations for the Building Energy Rating System [Appendix 2]: Use Profiles for Residential and Non-Residential Buildings
... A21: KR_etc_NoControl | B21: Constant | C21: 20 | D21: Industrial_Heating_Year | E21: 26 | F21: Industrial_Cooling_Year | G21: Celsius | H21: 건축물 에너지효율등급 인증제도 운영규정 [별표2] 주거 및 주거용 이외 건축물 용도프로필 / Operating Regulations for the Building Energy Rating System [Appendix 2]: Use Profiles for Residential and Non-Residential Buildings

Sheet Water_flow
A1: Name your variable. This should be something to recognize for the template assignment
A2: Name | B2: DHW_flow_rate | C2: Water_schedule | D2: Flow_rate_unit | E2: Source
A3: KR_res_sf | B3: 0.054 | C3: KR_res_sf_water | D3: m3/day/person | E3: 건축물 에너지효율등급 인증제도 운영규정 [별표2] 주거 및 주거용 이외 건축물 용도프로필 / Operating Regulations for the Building Energy Rating System [Appendix 2]: Use Profiles for Residential and Non-Residential Buildings
